<?xml version="1.0" ?>
<robot name="autonav" xmlns:xacro="http://www.ros.org/wiki/xacro">

<xacro:include filename="$(find autonav_description)/urdf/materials.xacro" />
<xacro:include filename="$(find autonav_description)/urdf/autonav.trans" />
<xacro:include filename="$(find autonav_description)/urdf/autonav.gazebo" />
<link name="base_link">
  <inertial>
    <origin xyz="-0.01990026970047047 -0.0015934183682931621 0.06326698419199289" rpy="0 0 0"/>
    <mass value="1.502681972626612"/>
    <inertia ixx="0.00875" iyy="0.004671" izz="0.008385" ixy="-4e-06" iyz="6e-06" ixz="-0.00088"/>
  </inertial>
  <visual>
    <origin xyz="0 0 0" rpy="0 0 0"/>
    <geometry>
      <mesh filename="package://autonav_description/meshes/base_link.stl" scale="0.001 0.001 0.001"/>
    </geometry>
    <material name="iron_cast"/>
  </visual>
  <collision>
    <origin xyz="0 0 0" rpy="0 0 0"/>
    <geometry>
      <mesh filename="package://autonav_description/meshes/base_link.stl" scale="0.001 0.001 0.001"/>
    </geometry>
  </collision>
</link>

<link name="rwheel_v1_1">
  <inertial>
    <origin xyz="-4.5057989165459e-07 -0.010000144695498703 -3.808221187284744e-07" rpy="0 0 0"/>
    <mass value="0.08557195733554016"/>
    <inertia ixx="2.9e-05" iyy="5.3e-05" izz="2.9e-05" ixy="-0.0" iyz="-0.0" ixz="0.0"/>
  </inertial>
  <visual>
    <origin xyz="0.039922 0.112112 -0.034999" rpy="0 0 0"/>
    <geometry>
      <mesh filename="package://autonav_description/meshes/rwheel_v1_1.stl" scale="0.001 0.001 0.001"/>
    </geometry>
    <material name="nylon_66_white"/>
  </visual>
  <collision>
    <origin xyz="0.039922 0.112112 -0.034999" rpy="0 0 0"/>
    <geometry>
      <mesh filename="package://autonav_description/meshes/rwheel_v1_1.stl" scale="0.001 0.001 0.001"/>
    </geometry>
  </collision>
</link>

<link name="lwheel_v1_1">
  <inertial>
    <origin xyz="-4.505798912313175e-07 0.009999855304501926 -3.808221200884976e-07" rpy="0 0 0"/>
    <mass value="0.08557195733554016"/>
    <inertia ixx="2.9e-05" iyy="5.3e-05" izz="2.9e-05" ixy="-0.0" iyz="0.0" ixz="0.0"/>
  </inertial>
  <visual>
    <origin xyz="0.039922 -0.108888 -0.034999" rpy="0 0 0"/>
    <geometry>
      <mesh filename="package://autonav_description/meshes/lwheel_v1_1.stl" scale="0.001 0.001 0.001"/>
    </geometry>
    <material name="nylon_66_white"/>
  </visual>
  <collision>
    <origin xyz="0.039922 -0.108888 -0.034999" rpy="0 0 0"/>
    <geometry>
      <mesh filename="package://autonav_description/meshes/lwheel_v1_1.stl" scale="0.001 0.001 0.001"/>
    </geometry>
  </collision>
</link>

<link name="ydlidar_x4_v2_1">
  <inertial>
    <origin xyz="4.659333779554348e-11 0.004720065458063468 0.037124378121149104" rpy="0 0 0"/>
    <mass value="0.16219033734231034"/>
    <inertia ixx="0.000129" iyy="7.9e-05" izz="0.00014" ixy="0.0" iyz="2e-05" ixz="0.0"/>
  </inertial>
  <visual>
    <origin xyz="-0.0 -0.00325 -0.196249" rpy="0 0 0"/>
    <geometry>
      <mesh filename="package://autonav_description/meshes/ydlidar_x4_v2_1.stl" scale="0.001 0.001 0.001"/>
    </geometry>
    <material name="abs_white"/>
  </visual>
  <collision>
    <origin xyz="-0.0 -0.00325 -0.196249" rpy="0 0 0"/>
    <geometry>
      <mesh filename="package://autonav_description/meshes/ydlidar_x4_v2_1.stl" scale="0.001 0.001 0.001"/>
    </geometry>
  </collision>
</link>

<joint name="Revolute 2" type="continuous">
  <origin xyz="-0.039922 -0.112112 0.034999" rpy="0 0 0"/>
  <parent link="base_link"/>
  <child link="rwheel_v1_1"/>
  <axis xyz="-0.0 1.0 -0.0"/>
</joint>

<joint name="Revolute 3" type="continuous">
  <origin xyz="-0.039922 0.108888 0.034999" rpy="0 0 0"/>
  <parent link="base_link"/>
  <child link="lwheel_v1_1"/>
  <axis xyz="-0.0 1.0 0.0"/>
</joint>

<joint name="Rigid 8" type="fixed">
  <origin xyz="0.0 0.00325 0.196249" rpy="0 0 0"/>
  <parent link="base_link"/>
  <child link="ydlidar_x4_v2_1"/>
</joint>

</robot>
